<?xml version='1.0'?>
<sdf version='1.4'>
  <model name='ur5'>
    <link name='shoulder_link'>
      <pose>0 0 0.089159 0 -0 0</pose>
      <inertial>
        <pose>0 0.00193 -0.02561 0 -0 0</pose>
        <mass>3.7</mass>
        <inertia>
          <ixx>1</ixx>
          <ixy>0</ixy>
          <ixz>0</ixz>
          <iyy>1</iyy>
          <iyz>0</iyz>
          <izz>1</izz>
        </inertia>
      </inertial>
      <collision name='shoulder_link_collision'>
        <pose>0 0 0 0 -0 0</pose>
        <geometry>
          <mesh>
            <scale>1 1 1</scale>
            <uri>model://universal-robot-ur5/meshes/ur5/collision/Shoulder.dae</uri>
          </mesh>
        </geometry>
      </collision>
      <visual name='shoulder_link_visual'>
        <pose>0 0 0 0 -0 0</pose>
        <geometry>
          <mesh>
            <scale>1 1 1</scale>
            <uri>model://universal-robot-ur5/meshes/ur5/visual/Shoulder.dae</uri>
          </mesh>
        </geometry>
      </visual>
      <velocity_decay>
        <linear>0</linear>
        <angular>0</angular>
      </velocity_decay>
    </link>
    <joint name='shoulder_pan_joint' type='revolute'>
      <child>shoulder_link</child>
      <parent>base_link</parent>
      <axis>
        <xyz>0 0 1</xyz>
        <limit>
          <lower>-6.28319</lower>
          <upper>6.28319</upper>
          <effort>10</effort>
          <velocity>3.14159</velocity>
        </limit>
        <dynamics>
          <damping>10</damping>
        </dynamics>
      </axis>
    </joint>
</model>
</sdf>
