<?xml version='1.0'?> 
<sdf version='1.4'> 
 <model name='Manipulator'> 
   <link name='linkkk'>
    <pose>0 0 0.089159 0 0 0</pose>
    <inertial> 
      <pose>0 0.00193 -0.02561 0 0 0</pose>
      <mass>4</mass>
      <inertia>
        <ixx>1</ixx>
        <iyy>1</iyy>
        <izz>1</izz>
        <ixy>0</ixy>
        <ixz>0</ixz>
        <iyz>0</iyz>
      </inertia>
    </inertial>
    <collision name = 'shoulder_link_collision'>
     <geometry> 
       <cylinder> 
         <radius>0.0375</radius>
         <length>1</length>
       </cylinder>
    </collision>
    <visual name = 'shoulder_link_visual_name'>
     <geometry> 
       <cylinder> 
         <radius>0.0375</radius>
         <length>1</length>
       </cylinder>
    </visual>
    <velocity_decay>
         <linear>0</linear> 
        <angular>0</angular> 
    </velocity_decay>
   </link>
   <joint name='shoulder_pan_joint' type='revolute'>
     <child>shoulder_link</child>
     <parent>base_link</parent>
     <axis>
       <xyz>0 0 1</xyz>
       <limit>
           <lower>-6.28319</lower>
           <upper>6.28319</upper>
           <effort>10</effort>
           <velocity>3.14159</velocity>
       </limit>
       <dynamics>
          <damping>10</damping>
       </dynamics>
     </axis>
   </joint>
 </model>   
</sdf> 
 